<?xml version="1.0"?>
<robot xmlns:xacro="http://www.ros.org/wiki/xacro" name="v2mini">

<xacro:property name="pi" value="3.14159" />

<xacro:property name="base_offsetx" value="-0.158825" />
<xacro:property name="base_offsety" value="-0.002" />
<xacro:property name="base_offsetz" value="0.407507" />

<xacro:macro name="arm">

  <link name="arm_link1">
    <visual>
      <origin xyz="0 0 0" rpy="0 0 0" />
      <geometry>
        <mesh filename="package://v2mini_description/meshes/arm/arm_link1.stl" />
      </geometry>
      <material name="black"/>
    </visual>
    <collision>
      <origin xyz="0 0 0" rpy="0 0 0"/>
      <geometry>
         <mesh filename="package://v2mini_description/meshes/arm/arm_link1.stl" />
      </geometry>
    </collision>
  </link>

  <!-- first additional joint at offset -->

  <link name="arm_link2">
    <visual>
      <origin xyz="0 0 0" rpy="0 ${pi} 0" />
      <geometry>
        <mesh filename="package://v2mini_description/meshes/arm/arm_link2.stl" />
      </geometry>
      <material name="grey"/>
    </visual>
    <collision>
       <origin xyz="0 0 0" rpy="0 ${pi} 0"/>
       <geometry>
            <mesh filename="package://v2mini_description/meshes/arm/arm_link2.stl" />
       </geometry>
    </collision>
  </link>

  <joint name="arm_joint1" type="revolute">
    <parent link="arm_link1"/>
    <child link="arm_link2"/>
    <origin xyz="${base_offsetx} ${base_offsety} ${base_offsetz}" rpy="${pi} ${pi} 0"/>
    <limit effort="1000.0" lower="-0.2" upper="2.85" velocity="0.1"/>
  </joint>

  <xacro:arm_link num="3" mat="black" par_num="2" axis="-1 0 0" offset="0.026 0 0" j_rpy="${pi/2} 0 ${3*pi/2}" l_rpy="0 ${-pi/2}  ${-pi/2}" limit_low="-0.3" limit_high="1.6"/>

  <xacro:arm_link num="4" mat="grey" par_num="3" axis="1 0 0" offset=" 0 0 -0.0855" j_rpy="0 ${pi/2} 0" l_rpy="${pi/2} ${pi}  0" limit_low="-3"  limit_high="3"/>

  <xacro:arm_link num="5" mat="black" par_num="4" axis="-1 0 0" offset="0.026 0 0" j_rpy=" ${-pi/2} 0 ${pi/2}" l_rpy="${-pi/2} 0 ${-pi/2}" limit_low="-1.5" limit_high="1.5"/>

  <xacro:arm_link num="6" mat="red" par_num="5" axis="-1 0 0" offset="0  0 -0.0415" j_rpy="${-pi/2} ${-pi/2} 0" l_rpy="${pi/2} ${pi/2} 0" limit_low="-3"  limit_high="3"/>

  <joint name="ee_joint" type="fixed">
      <parent link="arm_link6"/>
      <child link="ee_link"/>
      <origin xyz="0 0 0" rpy="0 0 0"/>
  </joint>

  <!-- Add end effector -->
  <link name="ee_link">
  <collision>
      <geometry>
          <box size="0.01 0.01 0.01"/>
      </geometry>
     <origin rpy="0 0 0" xyz="0 0 0"/>
  </collision>
  </link>

</xacro:macro>

<!-- macro for the rest of the links -->
<xacro:macro name="arm_link" params="num mat par_num axis offset j_rpy l_rpy limit_low limit_high ">

  <link name="arm_link${num}">
    <visual>
      <origin xyz="0 0 0" rpy="${l_rpy}" />
      <geometry>
        <mesh filename="package://v2mini_description/meshes/arm/arm_link${num}.stl" />
      </geometry>
      <material name="${mat}"/>
    </visual>
    <collision>
        <origin xyz="0 0 0" rpy="${l_rpy}"/>
        <geometry>
            <mesh filename="package://v2mini_description/meshes/arm/arm_link${num}.stl" />
        </geometry>
    </collision>
  </link>

  <joint name="arm_joint${par_num}" type="revolute">
    <parent link="arm_link${par_num}"/>
    <child link="arm_link${num}"/>
    <origin xyz="${offset}" rpy="${j_rpy}"/>
    <axis xyz="${axis}"/>
    <limit effort="1000.0" lower="${limit_low}" upper="${limit_high}" velocity="0.1"/>
  </joint>

</xacro:macro>

</robot>
