<?xml version="1.0" ?>
<!-- =================================================================================== -->
<!-- |    This document was autogenerated by xacro from v2mini_robot.urdf.xacro        | -->
<!-- |    EDITING THIS FILE BY HAND IS NOT RECOMMENDED                                 | -->
<!-- =================================================================================== -->
<robot name="v2mini" xmlns:xacro="http://www.ros.org/wiki/xacro">
  <!-- materials -->
  <material name="white">
    <color rgba="0.7 0.7 0.7 1"/>
  </material>
  <material name="blue">
    <color rgba="0.3 0.3 0.9 1"/>
  </material>
  <material name="black">
    <color rgba="0.2 0.2 0.2 1"/>
  </material>
  <material name="grey">
    <color rgba="0.4 0.4 0.4 1"/>
  </material>
  <material name="yellow">
    <color rgba="0.5 0.5 0.1 1"/>
  </material>
  <material name="red">
    <color rgba="0.6 0.2 0.2 1"/>
  </material>
  <!-- v2mini body -->
  <!-- base properties -->
  <!-- wheel properties -->
  <!-- torso properties -->
  <!-- Macro for creating base wheels -->
  <!-- v2mini arm -->
  <!-- macro for the rest of the links -->
  <!-- v2mini head -->
  <!-- join the body with arm -->
  <joint name="body_with_arm" type="fixed">
    <parent link="torso_link"/>
    <child link="arm_link1"/>
    <origin xyz="0 0 0"/>
  </joint>
  <!-- join the body with head -->
  <joint name="body_with_head" type="revolute">
    <parent link="torso_link"/>
    <child link="neck_link"/>
    <axis xyz="0 0 1"/>
    <origin xyz="0 0 0"/>
    <limit effort="1000.0" lower="-2.9" upper="2.9" velocity="0.1"/>
  </joint>
  <!-- **** BASE **** -->
  <link name="base_link">
    <visual>
      <origin rpy="0 0 0" xyz="0 0 0.0192"/>
      <geometry>
        <mesh filename="package://v2mini_description/meshes/base/base.stl"/>
      </geometry>
      <material name="white"/>
    </visual>
    <collision>
      <origin rpy="0 0 0" xyz="0 0 0.066"/>
      <geometry>
        <cylinder length="0.132" radius="0.175"/>
      </geometry>
    </collision>
  </link>
  <link name="front_wheel">
    <visual>
      <origin rpy="0 0 0.0" xyz="0 0 0"/>
      <geometry>
        <mesh filename="package://v2mini_description/meshes/base/base_wheel.stl"/>
      </geometry>
      <material name="red"/>
    </visual>
  </link>
  <joint name="front_axel" type="continuous">
    <parent link="base_link"/>
    <child link="front_wheel"/>
    <origin xyz="-0.0 -0.1405 0.03"/>
    <axis xyz="0.0 1 0"/>
  </joint>
  <link name="back_wheel">
    <visual>
      <origin rpy="0 0 3.14159" xyz="0 0 0"/>
      <geometry>
        <mesh filename="package://v2mini_description/meshes/base/base_wheel.stl"/>
      </geometry>
      <material name="red"/>
    </visual>
  </link>
  <joint name="back_axel" type="continuous">
    <parent link="base_link"/>
    <child link="back_wheel"/>
    <origin xyz="0.0 0.1405 0.03"/>
    <axis xyz="0.0 1 0"/>
  </joint>
  <link name="right_wheel">
    <visual>
      <origin rpy="0 0 -1.570795" xyz="0 0 0"/>
      <geometry>
        <mesh filename="package://v2mini_description/meshes/base/base_wheel.stl"/>
      </geometry>
      <material name="red"/>
    </visual>
  </link>
  <joint name="right_axel" type="continuous">
    <parent link="base_link"/>
    <child link="right_wheel"/>
    <origin xyz="-0.1405 -0.0 0.03"/>
    <axis xyz="1.0 0 0"/>
  </joint>
  <link name="left_wheel">
    <visual>
      <origin rpy="0 0 1.570795" xyz="0 0 0"/>
      <geometry>
        <mesh filename="package://v2mini_description/meshes/base/base_wheel.stl"/>
      </geometry>
      <material name="red"/>
    </visual>
  </link>
  <joint name="left_axel" type="continuous">
    <parent link="base_link"/>
    <child link="left_wheel"/>
    <origin xyz="0.1405 0.0 0.03"/>
    <axis xyz="1.0 0 0"/>
  </joint>
  <!-- **** TORSO **** -->
  <link name="torso_link">
    <visual>
      <origin rpy="0 0 0" xyz="0 0 0"/>
      <geometry>
        <mesh filename="package://v2mini_description/meshes/torso/torso.stl"/>
      </geometry>
      <material name="white"/>
    </visual>
  </link>
  <joint name="torso_slide" type="prismatic">
    <parent link="base_link"/>
    <child link="torso_link"/>
    <origin xyz="0 0 0.0192"/>
    <axis xyz="0 0 1"/>
    <limit effort="1000.0" lower="-0.09" upper="0" velocity="0.5"/>
  </joint>
  <link name="arm_link1">
    <visual>
      <origin rpy="0 0 0" xyz="0 0 0"/>
      <geometry>
        <mesh filename="package://v2mini_description/meshes/arm/arm_link1.stl"/>
      </geometry>
      <material name="black"/>
    </visual>
  </link>
  <!-- first additional joint at offset -->
  <link name="arm_link2">
    <visual>
      <origin rpy="0 0 0" xyz="0 0 0"/>
      <geometry>
        <mesh filename="package://v2mini_description/meshes/arm/arm_link2.stl"/>
      </geometry>
      <material name="grey"/>
    </visual>
  </link>
  <joint name="arm_joint1" type="revolute">
    <parent link="arm_link1"/>
    <child link="arm_link2"/>
    <origin xyz="-0.158825 -0.002 0.407507"/>
    <limit effort="1000.0" lower="-3.1" upper="3.1" velocity="0.1"/>
  </joint>
  <link name="arm_link3">
    <visual>
      <origin rpy="0 0 0" xyz="0 0 0"/>
      <geometry>
        <mesh filename="package://v2mini_description/meshes/arm/arm_link3.stl"/>
      </geometry>
      <material name="black"/>
    </visual>
  </link>
  <joint name="arm_joint2.0" type="revolute">
    <parent link="arm_link2"/>
    <child link="arm_link3"/>
    <origin xyz="-0.026 0 0"/>
    <axis xyz="0 1 0"/>
    <limit effort="1000.0" lower="-1.7" upper="1.7" velocity="0.1"/>
  </joint>
  <link name="arm_link4">
    <visual>
      <origin rpy="0 0 0" xyz="0 0 0"/>
      <geometry>
        <mesh filename="package://v2mini_description/meshes/arm/arm_link4.stl"/>
      </geometry>
      <material name="grey"/>
    </visual>
  </link>
  <joint name="arm_joint3.0" type="revolute">
    <parent link="arm_link3"/>
    <child link="arm_link4"/>
    <origin xyz="-0.0855 0 0"/>
    <axis xyz="1 0 0"/>
    <limit effort="1000.0" lower="-3.1" upper="3.1" velocity="0.1"/>
  </joint>
  <link name="arm_link5">
    <visual>
      <origin rpy="3.14159 0 0" xyz="0 0 0"/>
      <geometry>
        <mesh filename="package://v2mini_description/meshes/arm/arm_link5.stl"/>
      </geometry>
      <material name="black"/>
    </visual>
  </link>
  <joint name="arm_joint4.0" type="revolute">
    <parent link="arm_link4"/>
    <child link="arm_link5"/>
    <origin xyz="-0.026 0 0"/>
    <axis xyz="0 0 1"/>
    <limit effort="1000.0" lower="-3" upper="0.05" velocity="0.1"/>
  </joint>
  <link name="arm_link6">
    <visual>
      <origin rpy="0 0 0" xyz="0 0 0"/>
      <geometry>
        <mesh filename="package://v2mini_description/meshes/arm/arm_link6.stl"/>
      </geometry>
      <material name="red"/>
    </visual>
  </link>
  <joint name="arm_joint5.0" type="revolute">
    <parent link="arm_link5"/>
    <child link="arm_link6"/>
    <origin xyz="0 -0.0415 0"/>
    <axis xyz="0 1 0"/>
    <limit effort="1000.0" lower="-3.1" upper="3.1" velocity="0.1"/>
  </joint>
  <link name="neck_link">
    <visual>
      <origin rpy="0 0 0" xyz="0 0 0"/>
      <geometry>
        <mesh filename="package://v2mini_description/meshes/head/neck.stl"/>
      </geometry>
      <material name="black"/>
    </visual>
  </link>
  <link name="head_link">
    <visual>
      <origin rpy="0 0 0" xyz="0 0 0"/>
      <geometry>
        <mesh filename="package://v2mini_description/meshes/head/head.stl"/>
      </geometry>
      <material name="yellow"/>
    </visual>
  </link>
  <joint name="neck_tilt" type="revolute">
    <parent link="neck_link"/>
    <child link="head_link"/>
    <axis xyz="1 0 0"/>
    <origin xyz="0 0 0.495215"/>
    <limit effort="1000.0" lower="0.3" upper="-0.5" velocity="0.1"/>
  </joint>
</robot>

